[2024-03-01T00:56:24.783+0000] {taskinstance.py:1159} INFO - Dependencies all met for dep_context=non-requeueable deps ti=<TaskInstance: weather_data_upload.upload_weather_task scheduled__2024-02-29T00:00:00+00:00 [queued]>
[2024-03-01T00:56:24.790+0000] {taskinstance.py:1159} INFO - Dependencies all met for dep_context=requeueable deps ti=<TaskInstance: weather_data_upload.upload_weather_task scheduled__2024-02-29T00:00:00+00:00 [queued]>
[2024-03-01T00:56:24.790+0000] {taskinstance.py:1361} INFO - Starting attempt 1 of 1
[2024-03-01T00:56:24.798+0000] {taskinstance.py:1382} INFO - Executing <Task(PythonOperator): upload_weather_task> on 2024-02-29 00:00:00+00:00
[2024-03-01T00:56:24.801+0000] {standard_task_runner.py:57} INFO - Started process 410 to run task
[2024-03-01T00:56:24.804+0000] {standard_task_runner.py:84} INFO - Running: ['***', 'tasks', 'run', 'weather_data_upload', 'upload_weather_task', 'scheduled__2024-02-29T00:00:00+00:00', '--job-id', '23', '--raw', '--subdir', 'DAGS_FOLDER/weather_data_upload_dag.py', '--cfg-path', '/tmp/tmpbfpj0he0']
[2024-03-01T00:56:24.804+0000] {standard_task_runner.py:85} INFO - Job 23: Subtask upload_weather_task
[2024-03-01T00:56:24.836+0000] {task_command.py:416} INFO - Running <TaskInstance: weather_data_upload.upload_weather_task scheduled__2024-02-29T00:00:00+00:00 [running]> on host 87360dca8529
[2024-03-01T00:56:25.232+0000] {taskinstance.py:1662} INFO - Exporting env vars: AIRFLOW_CTX_DAG_OWNER='***' AIRFLOW_CTX_DAG_ID='weather_data_upload' AIRFLOW_CTX_TASK_ID='upload_weather_task' AIRFLOW_CTX_EXECUTION_DATE='2024-02-29T00:00:00+00:00' AIRFLOW_CTX_TRY_NUMBER='1' AIRFLOW_CTX_DAG_RUN_ID='scheduled__2024-02-29T00:00:00+00:00'
[2024-03-01T00:56:28.344+0000] {_metadata.py:139} WARNING - Compute Engine Metadata server unavailable on attempt 1 of 3. Reason: timed out
[2024-03-01T00:56:28.350+0000] {_metadata.py:139} WARNING - Compute Engine Metadata server unavailable on attempt 2 of 3. Reason: [Errno 111] Connection refused
[2024-03-01T00:56:28.352+0000] {_metadata.py:139} WARNING - Compute Engine Metadata server unavailable on attempt 3 of 3. Reason: [Errno 111] Connection refused
[2024-03-01T00:56:28.353+0000] {_default.py:338} WARNING - Authentication failed using Compute Engine authentication due to unavailable metadata server.
[2024-03-01T00:56:28.359+0000] {taskinstance.py:1937} ERROR - Task failed with exception
Traceback (most recent call last):
  File "/home/airflow/.local/lib/python3.8/site-packages/airflow/operators/python.py", line 192, in execute
    return_value = self.execute_callable()
  File "/home/airflow/.local/lib/python3.8/site-packages/airflow/operators/python.py", line 209, in execute_callable
    return self.python_callable(*self.op_args, **self.op_kwargs)
  File "/opt/airflow/plugins/sfweather_gbq_upload.py", line 11, in upload_weather_gbq
    pandas_gbq.to_gbq(
  File "/home/airflow/.local/lib/python3.8/site-packages/pandas_gbq/gbq.py", line 1164, in to_gbq
    connector = GbqConnector(
  File "/home/airflow/.local/lib/python3.8/site-packages/pandas_gbq/gbq.py", line 318, in __init__
    self.credentials, default_project = auth.get_credentials(
  File "/home/airflow/.local/lib/python3.8/site-packages/pandas_gbq/auth.py", line 56, in get_credentials
    credentials, default_project_id = pydata_google_auth.default(
  File "/home/airflow/.local/lib/python3.8/site-packages/pydata_google_auth/auth.py", line 152, in default
    credentials = get_user_credentials(
  File "/home/airflow/.local/lib/python3.8/site-packages/pydata_google_auth/auth.py", line 362, in get_user_credentials
    credentials = _webserver.run_local_server(app_flow, **AUTH_URI_KWARGS)
  File "/home/airflow/.local/lib/python3.8/site-packages/pydata_google_auth/_webserver.py", line 89, in run_local_server
    return app_flow.run_local_server(host=LOCALHOST, port=port, **kwargs)
  File "/home/airflow/.local/lib/python3.8/site-packages/google_auth_oauthlib/flow.py", line 444, in run_local_server
    webbrowser.get(browser).open(auth_url, new=1, autoraise=True)
  File "/usr/local/lib/python3.8/webbrowser.py", line 65, in get
    raise Error("could not locate runnable browser")
webbrowser.Error: could not locate runnable browser
[2024-03-01T00:56:28.379+0000] {taskinstance.py:1400} INFO - Marking task as FAILED. dag_id=weather_data_upload, task_id=upload_weather_task, execution_date=20240229T000000, start_date=20240301T005624, end_date=20240301T005628
[2024-03-01T00:56:28.392+0000] {standard_task_runner.py:104} ERROR - Failed to execute job 23 for task upload_weather_task (could not locate runnable browser; 410)
[2024-03-01T00:56:28.419+0000] {local_task_job_runner.py:228} INFO - Task exited with return code 1
[2024-03-01T00:56:28.436+0000] {taskinstance.py:2778} INFO - 0 downstream tasks scheduled from follow-on schedule check
